<?xml version="1.0"?>
<robot xmlns:xacro="http://www.ros.org/wiki/xacro" >

    <xacro:include filename="inertial_macros.xacro" />

    <material name="blue">
        <color rgba="0 0 1 1" />
    </material>

    <material name="green">
        <color rgba="0 1 0 1" />
    </material>

    <material name="grey">
        <color rgba="0.7 0.7 0.7 1" />
    </material>

    <material name="black">
        <color rgba="0 0 0 1" />
    </material>

    <!-- BASE LINK -->
    <link name="base_link">

    </link>

    <!-- Chassis LINK -->
    <link name="chassis">
        <visual>
            <geometry>
                <box size="0.6 0.4 0.2" />
            </geometry>
            <origin xyz="0 0 0.1" rpy="0 0 0" />
            <material name="green" />
        </visual>
        <collision>
            <geometry>
                <box size="0.6 0.4 0.2" />
            </geometry>
            <origin xyz="0 0 0.1" rpy="0 0 0" />
        </collision>
        <xacro:inertial_box mass="0.5" x="0.6" y="0.4" z="0.2">
            <origin xyz="0 0 0.1" rpy="0 0 0" />
        </xacro:inertial_box>
    </link>

    <joint name="chassis_joint" type="fixed">
        <parent link="base_link" />
        <child link="chassis" />
        <origin xyz="-0.1 0 0" />
    </joint>



    <gazebo reference="base_link">
        <material>Gazebo/Green</material>
    </gazebo>

    <!-- LEFT WHEEL LINK -->
    <link name="left_wheel_link">
        <visual>
            <geometry>
                <cylinder radius="0.1" length="0.05" />
            </geometry>
            <origin xyz="0 0 0" rpy="1.57 0 0" />
            <material name="grey" />
        </visual>
        <collision>
            <geometry>
                <cylinder radius="0.1" length="0.05" />
            </geometry>
            <origin xyz="0 0 0" rpy="1.57 0 0" />
        </collision>
        <xacro:inertial_cylinder mass="0.1" radius="0.1" length="0.05" >
            <origin xyz="0 0 0" rpy="1.57 0 0" />
        </xacro:inertial_cylinder>
    </link>

    <joint name="base_left_wheel_joint" type="continuous">
        <parent link="base_link" />
        <child link="left_wheel_link" />
        <origin xyz="-0.15 0.225 0" rpy="0 0 0" />
        <axis xyz="0 1 0" />
    </joint>

    <gazebo reference="left_wheel_link">
        <material>Gazebo/Grey</material>
    </gazebo>

    <!-- RIGHT WHEEL LINK -->
    <link name="right_wheel_link">
        <visual>
            <geometry>
                <cylinder radius="0.1" length="0.05" />
            </geometry>
            <origin xyz="0 0 0" rpy="1.57 0 0" />
            <material name="grey" />
        </visual>
        <collision>
            <geometry>
                <cylinder radius="0.1" length="0.05" />
            </geometry>
            <origin xyz="0 0 0" rpy="1.57 0 0" />
        </collision>
        <xacro:inertial_cylinder mass="0.1" radius="0.1" length="0.05" >
            <origin xyz="0 0 0" rpy="1.57 0 0" />
        </xacro:inertial_cylinder>
    </link>

    <joint name="base_right_wheel_joint" type="continuous">
        <parent link="base_link" />
        <child link="right_wheel_link" />
        <origin xyz="-0.15 -0.225 0" rpy="0 0 0" />
        <axis xyz="0 1 0" />
    </joint>

    <gazebo reference="right_wheel_link">
        <material>Gazebo/Grey</material>
    </gazebo>

    <!-- CASTER WHEEL LINK -->
    <link name="caster_wheel_link">
        <visual>
            <geometry>
                <sphere radius="0.1" />
            </geometry>
            <origin xyz="0 0 0" rpy="0 0 0" />
            <material name="grey" />
        </visual>
        <collision>
            <geometry>
                <sphere radius="0.1" />
            </geometry>
            <origin xyz="0 0 0" rpy="0 0 0" />
        </collision>
        <xacro:inertial_sphere mass="0.1" radius="0.05">
            <origin xyz="0 0 0" rpy="0 0 0" />
        </xacro:inertial_sphere>
    </link>

    <joint name="base_caster_wheel_joint" type="fixed">
        <parent link="base_link"/>
        <child link="caster_wheel_link"/>
        <origin xyz="0.1 0 0" rpy="0 0 0"/>
    </joint>

    <gazebo reference="caster_wheel_link">
        <material>Gazebo/Grey</material>
        <mu1 value ="0.001"/>
        <mu2 value ="0.001"/>
    </gazebo>
    
</robot>